Workbook

Sheet 매출
J1: 8월 | K1: 총 매출보고서 | U1: 선정릉점
C2: FC매출 | E2: PT매출 | G2: 전체 | J2: 매출 세부내역 ( 담당자 필터에서 담당자를 설정하시면 개인별 세부사항이 나옵니다 )
A3: 목표 | C3: 42000000 | E3: 73000000 | G3: =SUM(C3:F3) -> 115000000
A4: 달성매출 | C4: =SUM(A11:F11) -> 15859800 | E4: =SUM(G11) -> 40865000 | G4: =SUM(C4:F4) -> 56724800 | J4: 회원권 매출 | L4: 기타 매출 | N4: PT 매출 | P4: 환불 금액 | R4: 소득공제 | T4: 총매출
A5: 달성률 | C5: =IFERROR(SUM(C4/C3),"-") -> 0.37761429 | E5: =IFERROR(SUM(E4/E3),"-") -> 0.55979452 | G5: =IFERROR(SUM(G4/G3),"-") -> 0.49325913 | J5: =SUBTOTAL(109,I15:K494) -> 14489800 | L5: =SUBTOTAL(109,L15:N494) -> 1370000 | N5: =SUBTOTAL(109,O15:Q494) -> 40865000 | P5: =SUBTOTAL(109,R15:T494) -> 0 | R5: =SUBTOTAL(109,U15:U494) -> 2221000 | T5: =SUM(J5:Q5) -> 56724800
K7: 신규(수) | L7: 신규(매출) | M7: 재등록(수) | N7: 재등록(매출) | O7: 객단가 | R7: 신규(수) | S7: 신규(매출) | T7: 재등록(수) | U7: 재등록(매출) | W7: 객단가
J8: 회원권 | K8: =SUMPRODUCT(SUBTOTAL(102,OFFSET($D$15,ROW($D$15:$D$514)-ROW($D$15),))*($G$15:$G$514="신규")) -> 41 | L8: =SUMPRODUCT(SUBTOTAL(109,OFFSET($I$15,ROW($I$15:$I$514)-ROW($I$15),))*($G$15:$G$514="신규"))+SUMPRODUCT(SUBTOTAL(109,OFFSET($J$15,ROW($J$15:$J$514)-ROW($J$15),))*($G$15:$G$514="신규"))+SUMPRODUCT(SUBTOTAL(109,OFFSET($K$15,ROW($K$15:$K$514)-ROW($K$15),))*($G$15:$G$514="신규")) -> 9268300 | M8: =SUMPRODUCT(SUBTOTAL(102,OFFSET($D$15,ROW($D$15:$D$514)-ROW($D$15),))*($G$15:$G$514="재등록")) -> 15 | N8: =SUMPRODUCT(SUBTOTAL(109,OFFSET($I$15,ROW($I$15:$I$514)-ROW($I$15),))*($G$15:$G$514="재등록"))+SUMPRODUCT(SUBTOTAL(109,OFFSET($J$15,ROW($J$15:$J$514)-ROW($J$15),))*($G$15:$G$514="재등록"))+SUMPRODUCT(SUBTOTAL(109,OFFSET($K$15,ROW($K$15:$K$514)-ROW($K$15),))*($G$15:$G$514="재등록")) -> 4980600 | O8: =IFERROR(SUBTOTAL(109,I15:I514,J15:J514,K15:K514)/SUBTOTAL(109,D15:D514),"-") -> 40931.638 | Q8: PT | R8: =SUMPRODUCT(SUBTOTAL(102,OFFSET($E$15,ROW($E$15:$E$514)-ROW($E$15),))*($G$15:$G$514="신규")) -> 16 | S8: =SUMPRODUCT(SUBTOTAL(109,OFFSET($O$15,ROW($O$15:$O$514)-ROW($O$15),))*($G$15:$G$514="신규"))+SUMPRODUCT(SUBTOTAL(109,OFFSET($P$15,ROW($P$15:$P$514)-ROW($P$15),))*($G$15:$G$514="신규"))+SUMPRODUCT(SUBTOTAL(109,OFFSET($Q$15,ROW($Q$15:$Q$514)-ROW($Q$15),))*($G$15:$G$514="신규")) -> 18045000 | T8: =SUMPRODUCT(SUBTOTAL(102,OFFSET($E$15,ROW($E$15:$E$514)-ROW($E$15),))*($G$15:$G$514="재등록")) -> 11 | U8: =SUMPRODUCT(SUBTOTAL(109,OFFSET($O$15,ROW($O$15:$O$514)-ROW($O$15),))*($G$15:$G$514="재등록"))+SUMPRODUCT(SUBTOTAL(109,OFFSET($P$15,ROW($P$15:$P$514)-ROW($P$15),))*($G$15:$G$514="재등록"))+SUMPRODUCT(SUBTOTAL(109,OFFSET($Q$15,ROW($Q$15:$Q$514)-ROW($Q$15),))*($G$15:$G$514="재등록")) -> 22820000 | W8: =IFERROR(SUBTOTAL(109,O15:O514,P15:P514,Q15:Q514)/SUBTOTAL(109,E15:E514),"-") -> 58629.842
A10: 회원권 매출 | D10: 기타매출 | G10: PT매출 | I10: 월 총 매출 | K10: 환불 금액 | M10: 총 카드매출 | O10: 카드 외 매출 | Q10: 계좌 매출 | S10: 소득공제 | U10: 실 카드 외 매출
A11: =SUM(I15:K514)+SUM(R15:R514) -> 14489800 | D11: =SUM(L15:N514)+SUM(S15:S514) -> 1370000 | G11: =SUM(O15:Q514)+SUM(T15:T514) -> 40865000 | I11: =A11+D11+G11 -> 56724800 | K11: =SUM(R15:T494) -> 0 | M11: =SUM(I515,L515,O515) -> 52942800 | O11: =SUM(J515,M515,P515) -> 241000 | Q11: =SUM(K515,N515,Q515) -> 3541000 | S11: =SUM(U15:U494) -> 2221000 | U11: =O11+Q11-S11 -> 1561000
A13: 구분 | B13: 날짜 | C13: 성명 | D13: 회원권 기간 | E13: PT 세션 | F13: 기타 | G13: 신규 | H13: 담당자 | I13: 회원권 매출 | L13: 기타매출 | O13: PT매출 | R13: 환불 | U13: 소득공제 (중복기입) | V13: 비고 | W13: 카드사명
G14: 재등록 | I14: 카드 | J14: 카드 외 | K14: 계좌 | L14: 카드 | M14: 카드 외 | N14: 계좌 | O14: 카드 | P14: 카드 외 | Q14: 계좌 | R14: 회원권 | S14: 기타 | T14: PT
A15: =ROW()-14 -> 1 | B15: 1 | C15: 이지윤 | F15: 일일권 | G15: 재등록 | H15: 유세린 | L15: 20000 | W15: 하나카드
A16: =ROW()-14 -> 2 | B16: 1 | C16: 채호병 | D16: 12 | G16: 신규 | H16: 유세린 | I16: 429000 | L16: 33000 | W16: 현대카드
A17: =ROW()-14 -> 3 | B17: 2 | C17: 곽나영 | D17: 12 | G17: 신규 | H17: 유세린 | I17: 429000 | W17: 신한카드
A18: =ROW()-14 -> 4 | B18: 2 | C18: 이영신 | D18: 4 | G18: 재등록 | H18: 유세린 | I18: 207900 | W18: 비씨카드
A19: 5 | B19: 2 | C19: 한효원 | D19: 1 | F19: 운1 | G19: 재등록 | H19: 유세린 | I19: 154000 | L19: 11000 | W19: 비씨카드
A20: =ROW()-14 -> 6 | B20: 2 | C20: 김미라 | D20: 2 | F20: 운2 락2 | G20: 신규 | H20: 유세린 | I20: 69000 | L20: 44000 | W20: 우리카드
A21: =ROW()-14 -> 7 | B21: 2 | C21: 김미라 | E21: 4 | G21: 신규 | H21: 전현동 | O21: 80000 | W21: 우리카드
A22: =ROW()-14 -> 8 | B22: 3 | C22: 김민수 | D22: 6 | G22: 신규 | H22: 유세린 | I22: 240000 | W22: 비씨카드
A23: =ROW()-14 -> 9 | B23: 3 | C23: 안재형 | D23: 6 | G23: 신규 | H23: 유세린 | I23: 240000 | W23: 비씨카드
A24: =ROW()-14 -> 10 | B24: 3 | C24: 최슬기 | D24: 1 | G24: 신규 | H24: 유세린 | I24: 64000 | W24: 비씨카드
A25: =ROW()-14 -> 11 | B25: 3 | C25: 이케르 | E25: 10 | G25: 신규 | H25: 최성욱 | O25: 600000 | W25: 비씨카드
A26: =ROW()-14 -> 12 | B26: 3 | C26: 공태하 | D26: 12 | G26: 재등록 | H26: 유세린 | I26: 360000 | W26: 신한카드
A27: =ROW()-14 -> 13 | B27: 3 | C27: 전성필 | D27: 4 | G27: 신규 | H27: 유세린 | I27: 304700 | W27: 비씨카드20만/현대카드10만
A28: =ROW()-14 -> 14 | B28: 3 | C28: 이서린 | F28: 일일권 | G28: 재등록 | H28: 유세린 | L28: 20000 | W28: 하나카드
A29: =ROW()-14 -> 15 | B29: 3 | C29: 공규진 | F29: 운1 | G29: 신규 | H29: 유세린 | L29: 11000 | W29: 비씨카드
A30: =ROW()-14 -> 16 | B30: 3 | C30: 손민영 | F30: 결제변경 | H30: 장광희 | O30: -3000000 | W30: 하나카드
A31: =ROW()-14 -> 17 | B31: 3 | C31: 손민영 | F31: 결제변경 | H31: 장광희 | O31: 3000000 | W31: 국민카드
A32: =ROW()-14 -> 18 | B32: 3 | C32: 김미숙 | F32: 결제변경 | H32: 황용선 | I32: -690000 | O32: -1000000 | W32: 현대카드
A33: =ROW()-14 -> 19 | B33: 3 | C33: 김미숙 | F33: 결제변경 | H33: 황용선 | I33: 690000 | O33: 1000000 | W33: 신한카드
A34: =ROW()-14 -> 20 | B34: 4 | C34: 장대호 | F34: 락12 | G34: 신규 | H34: 유세린 | L34: 60000 | W34: 비씨카드
A35: =ROW()-14 -> 21 | B35: 4 | C35: 김유진 | D35: 4 | F35: 락4 | G35: 신규 | H35: 유세린 | I35: 207900 | L35: 44000 | W35: 비씨카드
A36: =ROW()-14 -> 22 | B36: 4 | C36: 이세영 | F36: 락4 | G36: 신규 | H36: 유세린 | L36: 40000 | W36: 삼성카드
A37: =ROW()-14 -> 23 | B37: 4 | C37: 박수현 | D37: 6 | G37: 신규 | H37: 유세린 | I37: 200000 | W37: 롯데카드,하나카드,우리카드,현대카드 687,500원
A38: =ROW()-14 -> 24 | B38: 4 | C38: 박수현 | E38: 52 | G38: 신규 | H38: 장광희 | O38: 2550000 | W38: 롯데카드,하나카드,우리카드,현대카드 687,500원
A39: =ROW()-14 -> 25 | B39: 5 | C39: 이하늘 | F39: 일일권 | G39: 신규 | H39: 유세린 | L39: 15000 | W39: 현대카드
A40: =ROW()-14 -> 26 | B40: 5 | C40: 엄재원 | D40: 4 | G40: 신규 | H40: 유세린 | I40: 207900 | W40: 비씨카드
A41: =ROW()-14 -> 27 | B41: 5 | C41: 윤성찬 | D41: 4 | G41: 신규 | H41: 유세린 | I41: 207900 | W41: 비씨카드
A42: =ROW()-14 -> 28 | B42: 6 | C42: 김지민 | D42: 4 | G42: 신규 | H42: 유세린 | I42: 189000 | W42: 비씨카드
A43: =ROW()-14 -> 29 | B43: 6 | C43: 김지민 | E43: 30 | G43: 신규 | H43: 변재용 | O43: 11000 | Q43: 1789000 | W43: 비씨카드11,000원/계좌이체1,789,000원
...

Sheet 매출순위
B3: PT 개인 매출 | G3: 성별 | H3: FC 개인 매출 | K3: 목 표 | L3: 매 출 | M3: 달성률 | N3: 지점
B4: 1 | C4: 매니저 | E4: =SUMIF(매출!$H$15:$H$514,D4,매출!$O$15:$O$514)+SUMIF(매출!$H$15:$H$514,D4,매출!$P$15:$P$514)+SUMIF(매출!$H$15:$H$514,D4,매출!$Q$15:$Q$514)+SUMIF(매출!$H$15:$H$514,D4,매출!$T$15:$T$514) -> 0 | F4: =매출!$U$1 -> 선정릉점 | H4: 1 | I4: 매니저 | K4: =매출!$C$3 -> 42000000 | L4: =SUM(L6:L14) -> 15859800 | M4: =IFERROR(L4/K4,"-") -> 0.37761429 | N4: =매출!$U$1 -> 선정릉점
B5: 2 | C5: 팀장 | D5: 변재용 | E5: =SUMIF(매출!$H$15:$H$514,D5,매출!$O$15:$O$514)+SUMIF(매출!$H$15:$H$514,D5,매출!$P$15:$P$514)+SUMIF(매출!$H$15:$H$514,D5,매출!$Q$15:$Q$514)+SUMIF(매출!$H$15:$H$514,D5,매출!$T$15:$T$514) -> 13108000 | F5: =매출!$U$1 -> 선정릉점 | H5: 2 | I5: 팀장 | K5: =매출!$C$3 -> 42000000 | L5: =SUM(L6:L14) -> 15859800 | M5: =IFERROR(L5/K5,"-") -> 0.37761429 | N5: =매출!$U$1 -> 선정릉점
B6: 3 | C6: 팀장 | D6: 장광희 | E6: =SUMIF(매출!$H$15:$H$514,D6,매출!$O$15:$O$514)+SUMIF(매출!$H$15:$H$514,D6,매출!$P$15:$P$514)+SUMIF(매출!$H$15:$H$514,D6,매출!$Q$15:$Q$514)+SUMIF(매출!$H$15:$H$514,D6,매출!$T$15:$T$514) -> 5602000 | F6: =매출!$U$1 -> 선정릉점 | H6: 3 | I6: 팀장 | L6: =SUMIF(매출!$H$15:$H$494,J6,매출!$I$15:$I$494)+SUMIF(매출!$H$15:$H$494,J6,매출!$J$15:$J$494)+SUMIF(매출!$H$15:$H$494,J6,매출!$K$15:$K$494)+SUMIF(매출!$H$15:$H$494,J6,매출!$R$15:$R$494)+SUMIF(매출!$H$15:$H$494,J6,매출!$L$15:$L$494)+SUMIF(매출!$H$15:$H$494,J6,매출!$M$15:$M$494)+SUMIF(매출!$H$15:$H$494,J6,매출!$S$15:$S$494)+SUMIF(매출!$H$15:$H$494,J6,매출!$N$15:$N$494) -> 0 | M6: =IFERROR(L6/K6,"-") -> - | N6: =매출!$U$1 -> 선정릉점
B7: 4 | C7: 시니어 | D7: 최성욱 | E7: =SUMIF(매출!$H$15:$H$514,D7,매출!$O$15:$O$514)+SUMIF(매출!$H$15:$H$514,D7,매출!$P$15:$P$514)+SUMIF(매출!$H$15:$H$514,D7,매출!$Q$15:$Q$514)+SUMIF(매출!$H$15:$H$514,D7,매출!$T$15:$T$514) -> 7855000 | F7: =매출!$U$1 -> 선정릉점 | H7: 4 | I7: 시니어 | J7: 유세린 | K7: 42000000 | L7: =SUMIF(매출!$H$15:$H$494,J7,매출!$I$15:$I$494)+SUMIF(매출!$H$15:$H$494,J7,매출!$J$15:$J$494)+SUMIF(매출!$H$15:$H$494,J7,매출!$K$15:$K$494)+SUMIF(매출!$H$15:$H$494,J7,매출!$R$15:$R$494)+SUMIF(매출!$H$15:$H$494,J7,매출!$L$15:$L$494)+SUMIF(매출!$H$15:$H$494,J7,매출!$M$15:$M$494)+SUMIF(매출!$H$15:$H$494,J7,매출!$S$15:$S$494)+SUMIF(매출!$H$15:$H$494,J7,매출!$N$15:$N$494) -> 15859800 | M7: =IFERROR(L7/K7,"-") -> 0.37761429 | N7: =매출!$U$1 -> 선정릉점
B8: 5 | C8: 시니어 | E8: =SUMIF(매출!$H$15:$H$514,D8,매출!$O$15:$O$514)+SUMIF(매출!$H$15:$H$514,D8,매출!$P$15:$P$514)+SUMIF(매출!$H$15:$H$514,D8,매출!$Q$15:$Q$514)+SUMIF(매출!$H$15:$H$514,D8,매출!$T$15:$T$514) -> 0 | F8: =매출!$U$1 -> 선정릉점 | H8: 5 | I8: 시니어 | L8: =SUMIF(매출!$H$15:$H$494,J8,매출!$I$15:$I$494)+SUMIF(매출!$H$15:$H$494,J8,매출!$J$15:$J$494)+SUMIF(매출!$H$15:$H$494,J8,매출!$K$15:$K$494)+SUMIF(매출!$H$15:$H$494,J8,매출!$R$15:$R$494)+SUMIF(매출!$H$15:$H$494,J8,매출!$L$15:$L$494)+SUMIF(매출!$H$15:$H$494,J8,매출!$M$15:$M$494)+SUMIF(매출!$H$15:$H$494,J8,매출!$S$15:$S$494)+SUMIF(매출!$H$15:$H$494,J8,매출!$N$15:$N$494) -> 0 | M8: =IFERROR(L8/K8,"-") -> - | N8: =매출!$U$1 -> 선정릉점
B9: 6 | C9: 시니어 | E9: =SUMIF(매출!$H$15:$H$514,D9,매출!$O$15:$O$514)+SUMIF(매출!$H$15:$H$514,D9,매출!$P$15:$P$514)+SUMIF(매출!$H$15:$H$514,D9,매출!$Q$15:$Q$514)+SUMIF(매출!$H$15:$H$514,D9,매출!$T$15:$T$514) -> 0 | F9: =매출!$U$1 -> 선정릉점 | H9: 6 | I9: 시니어 | L9: =SUMIF(매출!$H$15:$H$494,J9,매출!$I$15:$I$494)+SUMIF(매출!$H$15:$H$494,J9,매출!$J$15:$J$494)+SUMIF(매출!$H$15:$H$494,J9,매출!$K$15:$K$494)+SUMIF(매출!$H$15:$H$494,J9,매출!$R$15:$R$494)+SUMIF(매출!$H$15:$H$494,J9,매출!$L$15:$L$494)+SUMIF(매출!$H$15:$H$494,J9,매출!$M$15:$M$494)+SUMIF(매출!$H$15:$H$494,J9,매출!$S$15:$S$494)+SUMIF(매출!$H$15:$H$494,J9,매출!$N$15:$N$494) -> 0 | M9: =IFERROR(L9/K9,"-") -> - | N9: =매출!$U$1 -> 선정릉점
B10: 7 | C10: 시니어 | E10: =SUMIF(매출!$H$15:$H$514,D10,매출!$O$15:$O$514)+SUMIF(매출!$H$15:$H$514,D10,매출!$P$15:$P$514)+SUMIF(매출!$H$15:$H$514,D10,매출!$Q$15:$Q$514)+SUMIF(매출!$H$15:$H$514,D10,매출!$T$15:$T$514) -> 0 | F10: =매출!$U$1 -> 선정릉점 | H10: 7 | I10: 팀원 | L10: =SUMIF(매출!$H$15:$H$494,J10,매출!$I$15:$I$494)+SUMIF(매출!$H$15:$H$494,J10,매출!$J$15:$J$494)+SUMIF(매출!$H$15:$H$494,J10,매출!$K$15:$K$494)+SUMIF(매출!$H$15:$H$494,J10,매출!$R$15:$R$494)+SUMIF(매출!$H$15:$H$494,J10,매출!$L$15:$L$494)+SUMIF(매출!$H$15:$H$494,J10,매출!$M$15:$M$494)+SUMIF(매출!$H$15:$H$494,J10,매출!$S$15:$S$494)+SUMIF(매출!$H$15:$H$494,J10,매출!$N$15:$N$494) -> 0 | M10: =IFERROR(L10/K10,"-") -> - | N10: =매출!$U$1 -> 선정릉점
B11: 8 | C11: 시니어 | E11: =SUMIF(매출!$H$15:$H$514,D11,매출!$O$15:$O$514)+SUMIF(매출!$H$15:$H$514,D11,매출!$P$15:$P$514)+SUMIF(매출!$H$15:$H$514,D11,매출!$Q$15:$Q$514)+SUMIF(매출!$H$15:$H$514,D11,매출!$T$15:$T$514) -> 0 | F11: =매출!$U$1 -> 선정릉점 | H11: 8 | I11: 팀원 | L11: =SUMIF(매출!$H$15:$H$494,J11,매출!$I$15:$I$494)+SUMIF(매출!$H$15:$H$494,J11,매출!$J$15:$J$494)+SUMIF(매출!$H$15:$H$494,J11,매출!$K$15:$K$494)+SUMIF(매출!$H$15:$H$494,J11,매출!$R$15:$R$494)+SUMIF(매출!$H$15:$H$494,J11,매출!$L$15:$L$494)+SUMIF(매출!$H$15:$H$494,J11,매출!$M$15:$M$494)+SUMIF(매출!$H$15:$H$494,J11,매출!$S$15:$S$494)+SUMIF(매출!$H$15:$H$494,J11,매출!$N$15:$N$494) -> 0 | M11: =IFERROR(L11/K11,"-") -> - | N11: =매출!$U$1 -> 선정릉점
B12: 9 | C12: 팀원 | D12: 전현동 | E12: =SUMIF(매출!$H$15:$H$514,D12,매출!$O$15:$O$514)+SUMIF(매출!$H$15:$H$514,D12,매출!$P$15:$P$514)+SUMIF(매출!$H$15:$H$514,D12,매출!$Q$15:$Q$514)+SUMIF(매출!$H$15:$H$514,D12,매출!$T$15:$T$514) -> 3080000 | F12: =매출!$U$1 -> 선정릉점 | H12: 9 | I12: 팀원 | L12: =SUMIF(매출!$H$15:$H$494,J12,매출!$I$15:$I$494)+SUMIF(매출!$H$15:$H$494,J12,매출!$J$15:$J$494)+SUMIF(매출!$H$15:$H$494,J12,매출!$K$15:$K$494)+SUMIF(매출!$H$15:$H$494,J12,매출!$R$15:$R$494)+SUMIF(매출!$H$15:$H$494,J12,매출!$L$15:$L$494)+SUMIF(매출!$H$15:$H$494,J12,매출!$M$15:$M$494)+SUMIF(매출!$H$15:$H$494,J12,매출!$S$15:$S$494)+SUMIF(매출!$H$15:$H$494,J12,매출!$N$15:$N$494) -> 0 | M12: =IFERROR(L12/K12,"-") -> - | N12: =매출!$U$1 -> 선정릉점
B13: 10 | C13: 팀원 | D13: 조건우 | E13: =SUMIF(매출!$H$15:$H$514,D13,매출!$O$15:$O$514)+SUMIF(매출!$H$15:$H$514,D13,매출!$P$15:$P$514)+SUMIF(매출!$H$15:$H$514,D13,매출!$Q$15:$Q$514)+SUMIF(매출!$H$15:$H$514,D13,매출!$T$15:$T$514) -> 80000 | F13: =매출!$U$1 -> 선정릉점 | H13: 10 | I13: 팀원 | L13: =SUMIF(매출!$H$15:$H$494,J13,매출!$I$15:$I$494)+SUMIF(매출!$H$15:$H$494,J13,매출!$J$15:$J$494)+SUMIF(매출!$H$15:$H$494,J13,매출!$K$15:$K$494)+SUMIF(매출!$H$15:$H$494,J13,매출!$R$15:$R$494)+SUMIF(매출!$H$15:$H$494,J13,매출!$L$15:$L$494)+SUMIF(매출!$H$15:$H$494,J13,매출!$M$15:$M$494)+SUMIF(매출!$H$15:$H$494,J13,매출!$S$15:$S$494)+SUMIF(매출!$H$15:$H$494,J13,매출!$N$15:$N$494) -> 0 | M13: =IFERROR(L13/K13,"-") -> - | N13: =매출!$U$1 -> 선정릉점
B14: 11 | C14: 팀원 | D14: 김영인 | E14: =SUMIF(매출!$H$15:$H$514,D14,매출!$O$15:$O$514)+SUMIF(매출!$H$15:$H$514,D14,매출!$P$15:$P$514)+SUMIF(매출!$H$15:$H$514,D14,매출!$Q$15:$Q$514)+SUMIF(매출!$H$15:$H$514,D14,매출!$T$15:$T$514) -> 4290000 | F14: =매출!$U$1 -> 선정릉점 | H14: 11 | I14: 팀원 | L14: =SUMIF(매출!$H$15:$H$494,J14,매출!$I$15:$I$494)+SUMIF(매출!$H$15:$H$494,J14,매출!$J$15:$J$494)+SUMIF(매출!$H$15:$H$494,J14,매출!$K$15:$K$494)+SUMIF(매출!$H$15:$H$494,J14,매출!$R$15:$R$494)+SUMIF(매출!$H$15:$H$494,J14,매출!$L$15:$L$494)+SUMIF(매출!$H$15:$H$494,J14,매출!$M$15:$M$494)+SUMIF(매출!$H$15:$H$494,J14,매출!$S$15:$S$494)+SUMIF(매출!$H$15:$H$494,J14,매출!$N$15:$N$494) -> 0 | M14: =IFERROR(L14/K14,"-") -> - | N14: =매출!$U$1 -> 선정릉점
B15: 12 | C15: 팀원 | D15: 황용선 | E15: =SUMIF(매출!$H$15:$H$514,D15,매출!$O$15:$O$514)+SUMIF(매출!$H$15:$H$514,D15,매출!$P$15:$P$514)+SUMIF(매출!$H$15:$H$514,D15,매출!$Q$15:$Q$514)+SUMIF(매출!$H$15:$H$514,D15,매출!$T$15:$T$514) -> 6850000 | F15: =매출!$U$1 -> 선정릉점
B16: 13 | C16: 팀원 | E16: =SUMIF(매출!$H$15:$H$514,D16,매출!$O$15:$O$514)+SUMIF(매출!$H$15:$H$514,D16,매출!$P$15:$P$514)+SUMIF(매출!$H$15:$H$514,D16,매출!$Q$15:$Q$514)+SUMIF(매출!$H$15:$H$514,D16,매출!$T$15:$T$514) -> 0 | F16: =매출!$U$1 -> 선정릉점
B17: 14 | C17: 팀원 | E17: =SUMIF(매출!$H$15:$H$514,D17,매출!$O$15:$O$514)+SUMIF(매출!$H$15:$H$514,D17,매출!$P$15:$P$514)+SUMIF(매출!$H$15:$H$514,D17,매출!$Q$15:$Q$514)+SUMIF(매출!$H$15:$H$514,D17,매출!$T$15:$T$514) -> 0 | F17: =매출!$U$1 -> 선정릉점
B18: 15 | C18: 팀원 | E18: =SUMIF(매출!$H$15:$H$514,D18,매출!$O$15:$O$514)+SUMIF(매출!$H$15:$H$514,D18,매출!$P$15:$P$514)+SUMIF(매출!$H$15:$H$514,D18,매출!$Q$15:$Q$514)+SUMIF(매출!$H$15:$H$514,D18,매출!$T$15:$T$514) -> 0 | F18: =매출!$U$1 -> 선정릉점
B19: 16 | C19: 팀원 | E19: =SUMIF(매출!$H$15:$H$514,D19,매출!$O$15:$O$514)+SUMIF(매출!$H$15:$H$514,D19,매출!$P$15:$P$514)+SUMIF(매출!$H$15:$H$514,D19,매출!$Q$15:$Q$514)+SUMIF(매출!$H$15:$H$514,D19,매출!$T$15:$T$514) -> 0 | F19: =매출!$U$1 -> 선정릉점
B20: 17 | C20: 팀원 | E20: =SUMIF(매출!$H$15:$H$514,D20,매출!$O$15:$O$514)+SUMIF(매출!$H$15:$H$514,D20,매출!$P$15:$P$514)+SUMIF(매출!$H$15:$H$514,D20,매출!$Q$15:$Q$514)+SUMIF(매출!$H$15:$H$514,D20,매출!$T$15:$T$514) -> 0 | F20: =매출!$U$1 -> 선정릉점
B21: 18 | C21: 팀원 | E21: =SUMIF(매출!$H$15:$H$514,D21,매출!$O$15:$O$514)+SUMIF(매출!$H$15:$H$514,D21,매출!$P$15:$P$514)+SUMIF(매출!$H$15:$H$514,D21,매출!$Q$15:$Q$514)+SUMIF(매출!$H$15:$H$514,D21,매출!$T$15:$T$514) -> 0 | F21: =매출!$U$1 -> 선정릉점
B22: 19 | C22: 팀원 | E22: =SUMIF(매출!$H$15:$H$514,D22,매출!$O$15:$O$514)+SUMIF(매출!$H$15:$H$514,D22,매출!$P$15:$P$514)+SUMIF(매출!$H$15:$H$514,D22,매출!$Q$15:$Q$514)+SUMIF(매출!$H$15:$H$514,D22,매출!$T$15:$T$514) -> 0 | F22: =매출!$U$1 -> 선정릉점
B23: 20 | C23: 팀원 | E23: =SUMIF(매출!$H$15:$H$514,D23,매출!$O$15:$O$514)+SUMIF(매출!$H$15:$H$514,D23,매출!$P$15:$P$514)+SUMIF(매출!$H$15:$H$514,D23,매출!$Q$15:$Q$514)+SUMIF(매출!$H$15:$H$514,D23,매출!$T$15:$T$514) -> 0 | F23: =매출!$U$1 -> 선정릉점
B24: 21 | C24: 팀원 | E24: =SUMIF(매출!$H$15:$H$514,D24,매출!$O$15:$O$514)+SUMIF(매출!$H$15:$H$514,D24,매출!$P$15:$P$514)+SUMIF(매출!$H$15:$H$514,D24,매출!$Q$15:$Q$514)+SUMIF(매출!$H$15:$H$514,D24,매출!$T$15:$T$514) -> 0 | F24: =매출!$U$1 -> 선정릉점
B27: ※순위표 작성방법 : 회색 부분에만 작성 하고, 특이사항있을시 본사에 연락할 것

Sheet 페이롤
B1: =SUM(D6:D34)+SUM(D38:D72) -> 0 | G1: =매출!J1 -> 8월 | H1: 급여내역 | N1: =매출!U1 -> 선정릉점
B3: ※작성 매뉴얼 1. 회색으로 처리된 부분만 작성 가능
C5: 이름 | D5: 급여(세후) | E5: 급여(세전) | F5: 영업지원금 | G5: 목표매출 | H5: 매출 | I5: 커미션 | J5: 프로모션1 | K5: 프로모션2 | L5: 프로모션3 | M5: 오픈/마감 | N5: 기타
B6: FC 매니저 | D6: =E6*0.967 -> 0 | E6: =(F6+I6+J6+K6+L6+M6+N6) -> 0 | G6: =SUMIF(매출순위!$J$4:$J$14,C6,매출순위!$K$4:$K$14) -> 0 | H6: =SUMIF(매출순위!$J$4:$J$14,C6,매출순위!$L$4:$L$14) -> 0 | I6: =IFERROR(ROUNDDOWN(H6/G6*100,0)*10000,"0") -> 0
B7: FC 매니저 | D7: =E7*0.967 -> 0 | E7: =(F7+I7+J7+K7+L7+M7+N7) -> 0 | G7: =SUMIF(매출순위!$J$4:$J$14,C7,매출순위!$K$4:$K$14) -> 0 | H7: =SUMIF(매출순위!$J$4:$J$14,C7,매출순위!$L$4:$L$14) -> 0 | I7: =IFERROR(ROUNDDOWN(H7/G7*100,0)*10000,"0") -> 0
B8: FC 팀장 | D8: =E8*0.967 -> 0 | E8: =(F8+I8+J8+K8+L8+M8+N8) -> 0 | G8: =SUMIF(매출순위!$J$4:$J$14,C8,매출순위!$K$4:$K$14) -> 0 | H8: =SUMIF(매출순위!$J$4:$J$14,C8,매출순위!$L$4:$L$14) -> 0 | I8: =IFERROR(ROUNDDOWN(H8/G8*100,0)*10000,"0") -> 0
B9: FC 팀장 | D9: =E9*0.967 -> 0 | E9: =(F9+I9+J9+K9+L9+M9+N9) -> 0 | G9: =SUMIF(매출순위!$J$4:$J$14,C9,매출순위!$K$4:$K$14) -> 0 | H9: =SUMIF(매출순위!$J$4:$J$14,C9,매출순위!$L$4:$L$14) -> 0 | I9: =IFERROR(ROUNDDOWN(H9/G9*100,0)*10000,"0") -> 0
B10: FC 시니어 | D10: =E10*0.967 -> 0 | E10: =(F10+I10+J10+K10+L10+M10+N10) -> 0 | G10: =SUMIF(매출순위!$J$4:$J$14,C10,매출순위!$K$4:$K$14) -> 0 | H10: =SUMIF(매출순위!$J$4:$J$14,C10,매출순위!$L$4:$L$14) -> 0 | I10: =IFERROR(ROUNDDOWN(H10/G10*100,0)*10000,"0") -> 0
B11: FC 시니어 | D11: =E11*0.967 -> 0 | E11: =(F11+I11+J11+K11+L11+M11+N11) -> 0 | G11: =SUMIF(매출순위!$J$4:$J$14,C11,매출순위!$K$4:$K$14) -> 0 | H11: =SUMIF(매출순위!$J$4:$J$14,C11,매출순위!$L$4:$L$14) -> 0 | I11: =IFERROR(ROUNDDOWN(H11/G11*100,0)*10000,"0") -> 0
B12: FC 시니어 | D12: =E12*0.967 -> 0 | E12: =(F12+I12+J12+K12+L12+M12+N12) -> 0 | G12: =SUMIF(매출순위!$J$4:$J$14,C12,매출순위!$K$4:$K$14) -> 0 | H12: =SUMIF(매출순위!$J$4:$J$14,C12,매출순위!$L$4:$L$14) -> 0 | I12: =IFERROR(ROUNDDOWN(H12/G12*100,0)*10000,"0") -> 0
B13: FC 팀원 | D13: =E13*0.967 -> 0 | E13: =(F13+I13+J13+K13+L13+M13+N13) -> 0 | G13: =SUMIF(매출순위!$J$4:$J$14,C13,매출순위!$K$4:$K$14) -> 0 | H13: =SUMIF(매출순위!$J$4:$J$14,C13,매출순위!$L$4:$L$14) -> 0 | I13: =IFERROR(ROUNDDOWN(H13/G13*100,0)*10000,"0") -> 0
B14: FC 팀원 | D14: =E14*0.967 -> 0 | E14: =(F14+I14+J14+K14+L14+M14+N14) -> 0 | G14: =SUMIF(매출순위!$J$4:$J$14,C14,매출순위!$K$4:$K$14) -> 0 | H14: =SUMIF(매출순위!$J$4:$J$14,C14,매출순위!$L$4:$L$14) -> 0 | I14: =IFERROR(ROUNDDOWN(H14/G14*100,0)*10000,"0") -> 0
B15: FC 팀원 | D15: =E15*0.967 -> 0 | E15: =(F15+I15+J15+K15+L15+M15+N15) -> 0 | G15: =SUMIF(매출순위!$J$4:$J$14,C15,매출순위!$K$4:$K$14) -> 0 | H15: =SUMIF(매출순위!$J$4:$J$14,C15,매출순위!$L$4:$L$14) -> 0 | I15: =IFERROR(ROUNDDOWN(H15/G15*100,0)*10000,"0") -> 0
B16: FC 팀원 | D16: =E16*0.967 -> 0 | E16: =(F16+I16+J16+K16+L16+M16+N16) -> 0 | G16: =SUMIF(매출순위!$J$4:$J$14,C16,매출순위!$K$4:$K$14) -> 0 | H16: =SUMIF(매출순위!$J$4:$J$14,C16,매출순위!$L$4:$L$14) -> 0 | I16: =IFERROR(ROUNDDOWN(H16/G16*100,0)*10000,"0") -> 0
B17: FC 팀원 | D17: =E17*0.967 -> 0 | E17: =(F17+I17+J17+K17+L17+M17+N17) -> 0 | G17: =SUMIF(매출순위!$J$4:$J$14,C17,매출순위!$K$4:$K$14) -> 0 | H17: =SUMIF(매출순위!$J$4:$J$14,C17,매출순위!$L$4:$L$14) -> 0 | I17: =IFERROR(ROUNDDOWN(H17/G17*100,0)*10000,"0") -> 0
B18: FC 주니어 | D18: =E18*0.967 -> 0 | E18: =(F18+I18+J18+K18+L18+M18+N18) -> 0 | G18: =SUMIF(매출순위!$J$4:$J$14,C18,매출순위!$K$4:$K$14) -> 0 | H18: =SUMIF(매출순위!$J$4:$J$14,C18,매출순위!$L$4:$L$14) -> 0 | I18: =IFERROR(ROUNDDOWN(H18/G18*100,0)*5000,"0") -> 0
B19: FC 주니어 | D19: =E19*0.967 -> 0 | E19: =(F19+I19+J19+K19+L19+M19+N19) -> 0 | G19: =SUMIF(매출순위!$J$4:$J$14,C19,매출순위!$K$4:$K$14) -> 0 | H19: =SUMIF(매출순위!$J$4:$J$14,C19,매출순위!$L$4:$L$14) -> 0 | I19: =IFERROR(ROUNDDOWN(H19/G19*100,0)*5000,"0") -> 0
B20: CS | D20: =F20*(1.104) -> 0 | E20: =F20*(1.104) -> 0
B21: CS | D21: =F21*(1.104) -> 0 | E21: =F21*(1.104) -> 0
B22: CS | D22: =F22*(1.104) -> 0 | E22: =F22*(1.104) -> 0
B23: CS | D23: =F23*(1.104) -> 0 | E23: =F23*(1.104) -> 0
B24: 아르바이트 | D24: =F24*1.015 -> 0 | E24: =F24*1.015 -> 0
B25: 아르바이트 | D25: =F25*1.015 -> 0 | E25: =F25*1.015 -> 0
B26: 아르바이트 | D26: =F26*1.015 -> 0 | E26: =F26*1.015 -> 0
B27: 아르바이트 | D27: =F27*1.015 -> 0 | E27: =F27*1.015 -> 0
B28: 기타 | D28: =E28*0.967 -> 0 | E28: =(F28+I28+J28+K28+L28+M28+N28) -> 0
B29: 기타 | D29: =E29*0.967 -> 0 | E29: =(F29+I29+J29+K29+L29+M29+N29) -> 0
B30: 기타 | D30: =E30*0.967 -> 0 | E30: =(F30+I30+J30+K30+L30+M30+N30) -> 0
B31: 퇴사 직원 | D31: =E31*0.967 -> 0 | E31: =(F31+I31+J31+K31+L31+M31+N31) -> 0
B32: 퇴사 직원 | D32: =E32*0.967 -> 0 | E32: =(F32+I32+J32+K32+L32+M32+N32) -> 0
B33: 퇴사 직원 | D33: =E33*0.967 -> 0 | E33: =(F33+I33+J33+K33+L33+M33+N33) -> 0
B34: 퇴사 직원 | D34: =E34*0.967 -> 0 | E34: =(F34+I34+J34+K34+L34+M34+N34) -> 0
C37: 이름 | D37: 급여(세후) | E37: 급여(세전) | F37: 영업지원금 | G37: 수업료 | H37: 매출 | I37: 커미션 | J37: 프로모션1 | K37: 프로모션2 | L37: 프로모션3 | M37: 오픈/마감 | N37: 기타
B38: 지점장 | D38: =E38*0.967 -> 0 | E38: =(F38+G38+I38+J38+K38+L38+M38+N38) -> 0
B39: PT 매니저 | D39: =E39*0.967 -> 0 | E39: =(F39+G39+I39+J39+K39+L39+M39+N39) -> 0
B40: PT 팀장 | D40: =E40*0.967 -> 0 | E40: =(F40+G40+I40+J40+K40+L40+M40+N40) -> 0 | H40: =SUMIF(매출순위!$D$4:$D$24,C40,매출순위!$E$4:$E$24) -> 0 | I40: =(H40*0.9)*0.1 -> 0
B41: PT 팀장 | D41: =E41*0.967 -> 0 | E41: =(F41+G41+I41+J41+K41+L41+M41+N41) -> 0 | H41: =SUMIF(매출순위!$D$4:$D$24,C41,매출순위!$E$4:$E$24) -> 0 | I41: =(H41*0.9)*0.1 -> 0
B42: PT 시니어 | D42: =E42*0.967 -> 0 | E42: =(F42+G42+I42+J42+K42+L42+M42+N42) -> 0 | H42: =SUMIF(매출순위!$D$4:$D$24,C42,매출순위!$E$4:$E$24) -> 0 | I42: =IF(H42<7000000,H42*90%*10%,IF(H42<10000000,H42*90%*11%,IF(H42<15000000,H42*90%*12%,IF(15000000<=H42,H42*90%*13%)))) -> 0
B43: PT 시니어 | D43: =E43*0.967 -> 0 | E43: =(F43+G43+I43+J43+K43+L43+M43+N43) -> 0 | H43: =SUMIF(매출순위!$D$4:$D$24,C43,매출순위!$E$4:$E$24) -> 0 | I43: =IF(H43<7000000,H43*90%*10%,IF(H43<10000000,H43*90%*11%,IF(H43<15000000,H43*90%*12%,IF(15000000<=H43,H43*90%*13%)))) -> 0
B44: PT 시니어 | D44: =E44*0.967 -> 0 | E44: =(F44+G44+I44+J44+K44+L44+M44+N44) -> 0 | H44: =SUMIF(매출순위!$D$4:$D$24,C44,매출순위!$E$4:$E$24) -> 0 | I44: =IF(H44<7000000,H44*90%*10%,IF(H44<10000000,H44*90%*11%,IF(H44<15000000,H44*90%*12%,IF(15000000<=H44,H44*90%*13%)))) -> 0
...
